Workbook
Name Jira: Limpio!$A$1:$I$452
Name Jira: Ordenado!$A$1:$I$452
Name Jira: Tabla3!$B$1:$J$424
Name Jira: TODO!$A$1:$BC$452

Sheet TODO
A1: Resumen | B1: Clave de incidencia | C1: ID de la incidencia | D1: Tipo de Incidencia | E1: Estado | F1: Clave del proyecto | G1: Nombre del proyecto | H1: Tipo de proyecto | I1: Responsable del proyecto | J1: ID del responsable del proyecto | K1: Descripción del proyecto | L1: Prioridad | M1: Resolución | N1: Persona asignada | O1: ID de la persona asignada | P1: Informador | Q1: ID del informador | R1: Creador | S1: ID del creador | T1: Creada | U1: Actualizada | V1: Vista por Ãšltima Vez | W1: Resuelta | X1: Fecha de vencimiento | Y1: Votos | Z1: Descripción | AA1: Entorno | AB1: Interesados | AC1: ID de los interesados | AD1: Estimación original | AE1: Trabajo restante estimado | AF1: Tiempo Trabajado | AG1: Relación de trabajo | AH1: Î£ Estimación original | AI1: Î£ Trabajo restante estimado | AJ1: Î£ Tiempo empleado | AK1: Nivel de Seguridad | AL1: Enlace a la incidencia interna (Blocks) | AM1: Enlace de incidencia saliente (Blocks) | AN1: Enlace de incidencia saliente (Blocks) | AO1: Enlace de incidencia saliente (Blocks) | AP1: Enlace de incidencia saliente (Blocks) | AQ1: Campo personalizado (Issue color) | AR1: Campo personalizado (Rank) | AS1: Sprint | AT1: Campo personalizado (Start date) | AU1: Campo personalizado (Story point estimate) | AV1: Campo personalizado (Team) | AW1: Campo personalizado (Vulnerability) | AX1: Campo personalizado (development) | AY1: Categoría de estado | AZ1: Categoría de estado cambiada | BA1: Principal | BB1: Clave principal | BC1: Parent summary
A2: Integrar sistema de notificaciones con el flujo de compra | B2: MIP-457 | C2: 10945 | D2: Subtarea | E2: Tareas por hacer | F2: MIP | G2: Proyecto Intermodular | H2: software | I2: Alberto Puig Parellada | J2: 712020:5af7a3fc-6e7a-4877-a93a-01a122fcc36d | L2: Medium | N2: Alberto Puig Parellada | O2: 712020:5af7a3fc-6e7a-4877-a93a-01a122fcc36d | P2: Alberto Puig Parellada | Q2: 712020:5af7a3fc-6e7a-4877-a93a-01a122fcc36d | R2: Alberto Puig Parellada | S2: 712020:5af7a3fc-6e7a-4877-a93a-01a122fcc36d | T2: 45970.479 | U2: 45983.463 | V2: 45983.441 | Y2: 0 | Z2: Asegurarse de que la notificación por correo electrónico se envíe automáticamente al finalizar el proceso de compra exitosamente. | AB2: Alberto Puig Parellada | AC2: 712020:5af7a3fc-6e7a-4877-a93a-01a122fcc36d | AR2: 0|i002mf: | AS2: Semanas 17 - 18 | AU2: 43.0 | AY2: Por hacer | AZ2: 45970.479 | BA2: 10173 | BB2: MIP-84 | BC2: Enviar notificación por correo electrónico
A3: Realizar pruebas de envío de notificaciones por correo electrónico | B3: MIP-456 | C3: 10944 | D3: Subtarea | E3: Tareas por hacer | F3: MIP | G3: Proyecto Intermodular | H3: software | I3: Alberto Puig Parellada | J3: 712020:5af7a3fc-6e7a-4877-a93a-01a122fcc36d | L3: Medium | N3: Alberto Puig Parellada | O3: 712020:5af7a3fc-6e7a-4877-a93a-01a122fcc36d | P3: Alberto Puig Parellada | Q3: 712020:5af7a3fc-6e7a-4877-a93a-01a122fcc36d | R3: Alberto Puig Parellada | S3: 712020:5af7a3fc-6e7a-4877-a93a-01a122fcc36d | T3: 45970.479 | U3: 45983.463 | Y3: 0 | Z3: Probar el envío de correos electrónicos para verificar que la información enviada sea correcta y que el correo llegue al destinatario. | AB3: Alberto Puig Parellada | AC3: 712020:5af7a3fc-6e7a-4877-a93a-01a122fcc36d | AR3: 0|i002lz: | AS3: Semanas 17 - 18 | AU3: 43.0 | AY3: Por hacer | AZ3: 45970.479 | BA3: 10173 | BB3: MIP-84 | BC3: Enviar notificación por correo electrónico
A4: Implementar lógica para generar y enviar notificación por correo electrónico | B4: MIP-454 | C4: 10943 | D4: Subtarea | E4: Tareas por hacer | F4: MIP | G4: Proyecto Intermodular | H4: software | I4: Alberto Puig Parellada | J4: 712020:5af7a3fc-6e7a-4877-a93a-01a122fcc36d | L4: Medium | N4: Alberto Puig Parellada | O4: 712020:5af7a3fc-6e7a-4877-a93a-01a122fcc36d | P4: Alberto Puig Parellada | Q4: 712020:5af7a3fc-6e7a-4877-a93a-01a122fcc36d | R4: Alberto Puig Parellada | S4: 712020:5af7a3fc-6e7a-4877-a93a-01a122fcc36d | T4: 45970.479 | U4: 45983.463 | Y4: 0 | Z4: Desarrollar la funcionalidad que genere y envíe el correo electrónico al usuario después de realizar una compra, utilizando la plantilla diseñada. | AB4: Alberto Puig Parellada | AC4: 712020:5af7a3fc-6e7a-4877-a93a-01a122fcc36d | AR4: 0|i002m7: | AS4: Semanas 17 - 18 | AU4: 43.0 | AY4: Por hacer | AZ4: 45970.479 | BA4: 10173 | BB4: MIP-84 | BC4: Enviar notificación por correo electrónico
A5: Documentar el proceso de notificación por correo electrónico | B5: MIP-455 | C5: 10942 | D5: Subtarea | E5: Tareas por hacer | F5: MIP | G5: Proyecto Intermodular | H5: software | I5: Alberto Puig Parellada | J5: 712020:5af7a3fc-6e7a-4877-a93a-01a122fcc36d | L5: Medium | N5: Alberto Puig Parellada | O5: 712020:5af7a3fc-6e7a-4877-a93a-01a122fcc36d | P5: Alberto Puig Parellada | Q5: 712020:5af7a3fc-6e7a-4877-a93a-01a122fcc36d | R5: Alberto Puig Parellada | S5: 712020:5af7a3fc-6e7a-4877-a93a-01a122fcc36d | T5: 45970.479 | U5: 45983.463 | Y5: 0 | Z5: Crear documentación técnica y de usuario sobre cómo funciona el sistema de notificaciones por correo electrónico y qué información se incluye. | AB5: Alberto Puig Parellada | AC5: 712020:5af7a3fc-6e7a-4877-a93a-01a122fcc36d | AR5: 0|i002lr: | AS5: Semanas 17 - 18 | AU5: 43.0 | AY5: Por hacer | AZ5: 45970.479 | BA5: 10173 | BB5: MIP-84 | BC5: Enviar notificación por correo electrónico
A6: Mostrar mensajes de éxito o error tras el pago | B6: MIP-453 | C6: 10937 | D6: Subtarea | E6: Tareas por hacer | F6: MIP | G6: Proyecto Intermodular | H6: software | I6: Alberto Puig Parellada | J6: 712020:5af7a3fc-6e7a-4877-a93a-01a122fcc36d | L6: Medium | N6: Alberto Puig Parellada | O6: 712020:5af7a3fc-6e7a-4877-a93a-01a122fcc36d | P6: Alberto Puig Parellada | Q6: 712020:5af7a3fc-6e7a-4877-a93a-01a122fcc36d | R6: Alberto Puig Parellada | S6: 712020:5af7a3fc-6e7a-4877-a93a-01a122fcc36d | T6: 45970.479 | U6: 45983.463 | Y6: 0 | Z6: Implementar la lógica para mostrar mensajes claros al usuario según el resultado del intento de pago (éxito, error, datos incorrectos, etc.). | AB6: Alberto Puig Parellada | AC6: 712020:5af7a3fc-6e7a-4877-a93a-01a122fcc36d | AR6: 0|i002lj: | AS6: Semanas 15 - 16 | AU6: 52.0 | AY6: Por hacer | AZ6: 45970.479 | BA6: 10169 | BB6: MIP-82 | BC6: Mostrar formulario de pago para la suscripción premium
A7: Probar el formulario de pago en diferentes dispositivos y navegadores | B7: MIP-452 | C7: 10936 | D7: Subtarea | E7: Tareas por hacer | F7: MIP | G7: Proyecto Intermodular | H7: software | I7: Alberto Puig Parellada | J7: 712020:5af7a3fc-6e7a-4877-a93a-01a122fcc36d | L7: Medium | N7: Alberto Puig Parellada | O7: 712020:5af7a3fc-6e7a-4877-a93a-01a122fcc36d | P7: Alberto Puig Parellada | Q7: 712020:5af7a3fc-6e7a-4877-a93a-01a122fcc36d | R7: Alberto Puig Parellada | S7: 712020:5af7a3fc-6e7a-4877-a93a-01a122fcc36d | T7: 45970.479 | U7: 45983.463 | Y7: 0 | Z7: Realizar pruebas funcionales y de usabilidad del formulario de pago en distintos dispositivos y navegadores para asegurar su correcto funcionamiento. | AB7: Alberto Puig Parellada | AC7: 712020:5af7a3fc-6e7a-4877-a93a-01a122fcc36d | AR7: 0|i002l3: | AS7: Semanas 15 - 16 | AU7: 52.0 | AY7: Por hacer | AZ7: 45970.479 | BA7: 10169 | BB7: MIP-82 | BC7: Mostrar formulario de pago para la suscripción premium
A8: Integrar el formulario con la pasarela de pago | B8: MIP-451 | C8: 10934 | D8: Subtarea | E8: Tareas por hacer | F8: MIP | G8: Proyecto Intermodular | H8: software | I8: Alberto Puig Parellada | J8: 712020:5af7a3fc-6e7a-4877-a93a-01a122fcc36d | L8: Medium | N8: Alberto Puig Parellada | O8: 712020:5af7a3fc-6e7a-4877-a93a-01a122fcc36d | P8: Alberto Puig Parellada | Q8: 712020:5af7a3fc-6e7a-4877-a93a-01a122fcc36d | R8: Alberto Puig Parellada | S8: 712020:5af7a3fc-6e7a-4877-a93a-01a122fcc36d | T8: 45970.479 | U8: 45983.463 | Y8: 0 | Z8: Conectar el formulario de pago con la pasarela de pago seleccionada para procesar los pagos de la suscripción premium. | AB8: Alberto Puig Parellada | AC8: 712020:5af7a3fc-6e7a-4877-a93a-01a122fcc36d | AR8: 0|i002lb: | AS8: Semanas 15 - 16 | AU8: 52.0 | AY8: Por hacer | AZ8: 45970.479 | BA8: 10169 | BB8: MIP-82 | BC8: Mostrar formulario de pago para la suscripción premium
A9: Implementar campos y validaciones del formulario de pago | B9: MIP-450 | C9: 10935 | D9: Subtarea | E9: Tareas por hacer | F9: MIP | G9: Proyecto Intermodular | H9: software | I9: Alberto Puig Parellada | J9: 712020:5af7a3fc-6e7a-4877-a93a-01a122fcc36d | L9: Medium | N9: Alberto Puig Parellada | O9: 712020:5af7a3fc-6e7a-4877-a93a-01a122fcc36d | P9: Alberto Puig Parellada | Q9: 712020:5af7a3fc-6e7a-4877-a93a-01a122fcc36d | R9: Alberto Puig Parellada | S9: 712020:5af7a3fc-6e7a-4877-a93a-01a122fcc36d | T9: 45970.479 | U9: 45983.463 | Y9: 0 | Z9: Desarrollar los campos necesarios (nombre, número de tarjeta, fecha de expiración, CVV, etc.) y agregar validaciones para asegurar la correcta introducción de los datos. | AB9: Alberto Puig Parellada | AC9: 712020:5af7a3fc-6e7a-4877-a93a-01a122fcc36d | AR9: 0|i002kv: | AS9: Semanas 15 - 16 | AU9: 52.0 | AY9: Por hacer | AZ9: 45970.479 | BA9: 10169 | BB9: MIP-82 | BC9: Mostrar formulario de pago para la suscripción premium
A10: Realizar pruebas de visualización de anuncios en diferentes dispositivos | B10: MIP-449 | C10: 10929 | D10: Subtarea | E10: Tareas por hacer | F10: MIP | G10: Proyecto Intermodular | H10: software | I10: Alberto Puig Parellada | J10: 712020:5af7a3fc-6e7a-4877-a93a-01a122fcc36d | L10: Medium | N10: Alberto Puig Parellada | O10: 712020:5af7a3fc-6e7a-4877-a93a-01a122fcc36d | P10: Alberto Puig Parellada | Q10: 712020:5af7a3fc-6e7a-4877-a93a-01a122fcc36d | R10: Alberto Puig Parellada | S10: 712020:5af7a3fc-6e7a-4877-a93a-01a122fcc36d | T10: 45970.479 | U10: 45983.464 | Y10: 0 | Z10: Probar la correcta visualización y funcionamiento de los anuncios en las listas de quedadas en distintos dispositivos y resoluciones. | AB10: Alberto Puig Parellada | AC10: 712020:5af7a3fc-6e7a-4877-a93a-01a122fcc36d | AR10: 0|i002kn: | AS10: Semanas 17 - 18 | AU10: 22.0 | AY10: Por hacer | AZ10: 45970.479 | BA10: 10163 | BB10: MIP-79 | BC10: Mostrar anuncios en las listas de quedadas
A11: Implementar la lógica para mostrar anuncios solo a usuarios no premium | B11: MIP-448 | C11: 10927 | D11: Subtarea | E11: Tareas por hacer | F11: MIP | G11: Proyecto Intermodular | H11: software | I11: Alberto Puig Parellada | J11: 712020:5af7a3fc-6e7a-4877-a93a-01a122fcc36d | L11: Medium | N11: Alberto Puig Parellada | O11: 712020:5af7a3fc-6e7a-4877-a93a-01a122fcc36d | P11: Alberto Puig Parellada | Q11: 712020:5af7a3fc-6e7a-4877-a93a-01a122fcc36d | R11: Alberto Puig Parellada | S11: 712020:5af7a3fc-6e7a-4877-a93a-01a122fcc36d | T11: 45970.479 | U11: 45983.463 | Y11: 0 | Z11: Desarrollar la funcionalidad que verifica el tipo de usuario y muestra anuncios únicamente a los usuarios no premium en las listas de quedadas. | AB11: Alberto Puig Parellada | AC11: 712020:5af7a3fc-6e7a-4877-a93a-01a122fcc36d | AR11: 0|i002kf: | AS11: Semanas 17 - 18 | AU11: 22.0 | AY11: Por hacer | AZ11: 45970.479 | BA11: 10163 | BB11: MIP-79 | BC11: Mostrar anuncios en las listas de quedadas
A12: Recopilar métricas básicas de visualización de anuncios | B12: MIP-446 | C12: 10926 | D12: Subtarea | E12: Tareas por hacer | F12: MIP | G12: Proyecto Intermodular | H12: software | I12: Alberto Puig Parellada | J12: 712020:5af7a3fc-6e7a-4877-a93a-01a122fcc36d | L12: Medium | N12: Alberto Puig Parellada | O12: 712020:5af7a3fc-6e7a-4877-a93a-01a122fcc36d | P12: Alberto Puig Parellada | Q12: 712020:5af7a3fc-6e7a-4877-a93a-01a122fcc36d | R12: Alberto Puig Parellada | S12: 712020:5af7a3fc-6e7a-4877-a93a-01a122fcc36d | T12: 45970.479 | U12: 45983.463 | Y12: 0 | Z12: Implementar la recopilación de datos sobre la visualización de anuncios (impresiones, clics) para futuras mejoras y análisis. | AB12: Alberto Puig Parellada | AC12: 712020:5af7a3fc-6e7a-4877-a93a-01a122fcc36d | AR12: 0|i002k7: | AS12: Semanas 17 - 18 | AU12: 22.0 | AY12: Por hacer | AZ12: 45970.479 | BA12: 10163 | BB12: MIP-79 | BC12: Mostrar anuncios en las listas de quedadas
A13: Integrar el sistema de anuncios con el backend de las listas de quedadas | B13: MIP-447 | C13: 10925 | D13: Subtarea | E13: Tareas por hacer | F13: MIP | G13: Proyecto Intermodular | H13: software | I13: Alberto Puig Parellada | J13: 712020:5af7a3fc-6e7a-4877-a93a-01a122fcc36d | L13: Medium | N13: Alberto Puig Parellada | O13: 712020:5af7a3fc-6e7a-4877-a93a-01a122fcc36d | P13: Alberto Puig Parellada | Q13: 712020:5af7a3fc-6e7a-4877-a93a-01a122fcc36d | R13: Alberto Puig Parellada | S13: 712020:5af7a3fc-6e7a-4877-a93a-01a122fcc36d | T13: 45970.479 | U13: 45983.463 | Y13: 0 | Z13: Conectar el sistema de anuncios existente o nuevo con el backend que gestiona las listas de quedadas para que los anuncios se carguen dinámicamente. | AB13: Alberto Puig Parellada | AC13: 712020:5af7a3fc-6e7a-4877-a93a-01a122fcc36d | AR13: 0|i002jz: | AS13: Semanas 17 - 18 | AU13: 22.0 | AY13: Por hacer | AZ13: 45970.479 | BA13: 10163 | BB13: MIP-79 | BC13: Mostrar anuncios en las listas de quedadas
A14: Implementar el botón de premium en la interfaz del perfil | B14: MIP-444 | C14: 10921 | D14: Subtarea | E14: Tareas por hacer | F14: MIP | G14: Proyecto Intermodular | H14: software | I14: Alberto Puig Parellada | J14: 712020:5af7a3fc-6e7a-4877-a93a-01a122fcc36d | L14: Medium | N14: Alberto Puig Parellada | O14: 712020:5af7a3fc-6e7a-4877-a93a-01a122fcc36d | P14: Alberto Puig Parellada | Q14: 712020:5af7a3fc-6e7a-4877-a93a-01a122fcc36d | R14: Alberto Puig Parellada | S14: 712020:5af7a3fc-6e7a-4877-a93a-01a122fcc36d | T14: 45970.478 | U14: 45983.463 | Y14: 0 | Z14: Agregar el botón de premium en la vista del perfil de usuario, asegurando su correcta ubicación y visibilidad. | AB14: Alberto Puig Parellada | AC14: 712020:5af7a3fc-6e7a-4877-a93a-01a122fcc36d | AR14: 0|i002jr: | AS14: Semana 10 | AU14: 38.0 | AY14: Por hacer | AZ14: 45970.478 | BA14: 10165 | BB14: MIP-80 | BC14: Mostrar botón de premium en el perfil
... A135: Gestionar estados vacíos y errores en la lista de amistades | B135: MIP-324 | C135: 10679 | D135: Subtarea | E135: Tareas por hacer | F135: MIP | G135: Proyecto Intermodular | H135: software | I135: Alberto Puig Parellada | J135: 712020:5af7a3fc-6e7a-4877-a93a-01a122fcc36d | L135: Medium | N135: Alberto Puig Parellada | O135: 712020:5af7a3fc-6e7a-4877-a93a-01a122fcc36d | P135: Alberto Puig Parellada | Q135: 712020:5af7a3fc-6e7a-4877-a93a-01a122fcc36d | R135: Alberto Puig Parellada | S135: 712020:5af7a3fc-6e7a-4877-a93a-01a122fcc36d | T135: 45970.474 | U135: 45982.856 | Y135: 0 | Z135: Implementar el manejo de casos en los que el usuario no tenga amistades o se produzca un error al cargar la lista, mostrando mensajes apropiados. | AB135: Alberto Puig Parellada | AC135: 712020:5af7a3fc-6e7a-4877-a93a-01a122fcc36d | AR135: 0|i001sv: | AS135: Semana 9 | AU135: 15.0 | AY135: Por hacer | AZ135: 45970.474 | BA135: 10239 | BB135: MIP-120 | BC135: Mostrar lista de amistades
A136: Mostrar la lista de amistades en la interfaz de usuario | B136: MIP-323 | C136: 10677 | D136: Subtarea | E136: Tareas por hacer | F136: MIP | G136: Proyecto Intermodular | H136: software | I136: Alberto Puig Parellada | J136: 712020:5af7a3fc-6e7a-4877-a93a-01a122fcc36d | L136: Medium | N136: Alberto Puig Parellada | O136: 712020:5af7a3fc-6e7a-4877-a93a-01a122fcc36d | P136: Alberto Puig Parellada | Q136: 712020:5af7a3fc-6e7a-4877-a93a-01a122fcc36d | R136: Alberto Puig Parellada | S136: 712020:5af7a3fc-6e7a-4877-a93a-01a122fcc36d | T136: 45970.474 | U136: 45982.856 | V136: 45982.824 | Y136: 0 | Z136: Programar la visualización de la lista de amistades en la aplicación, mostrando los datos relevantes de cada amigo. | AB136: Alberto Puig Parellada | AC136: 712020:5af7a3fc-6e7a-4877-a93a-01a122fcc36d | AR136: 0|i001sn: | AS136: Semana 9 | AU136: 15.0 | AY136: Por hacer | AZ136: 45970.474 | BA136: 10239 | BB136: MIP-120 | BC136: Mostrar lista de amistades
A137: Implementar la lógica para obtener la lista de amistades del backend | B137: MIP-322 | C137: 10675 | D137: Subtarea | E137: Tareas por hacer | F137: MIP | G137: Proyecto Intermodular | H137: software | I137: Alberto Puig Parellada | J137: 712020:5af7a3fc-6e7a-4877-a93a-01a122fcc36d | L137: Medium | N137: Alberto Puig Parellada | O137: 712020:5af7a3fc-6e7a-4877-a93a-01a122fcc36d | P137: Alberto Puig Parellada | Q137: 712020:5af7a3fc-6e7a-4877-a93a-01a122fcc36d | R137: Alberto Puig Parellada | S137: 712020:5af7a3fc-6e7a-4877-a93a-01a122fcc36d | T137: 45970.474 | U137: 45982.856 | Y137: 0 | Z137: Desarrollar la funcionalidad que permite recuperar la lista de amistades asociadas al usuario desde el servidor o base de datos. | AB137: Alberto Puig Parellada | AC137: 712020:5af7a3fc-6e7a-4877-a93a-01a122fcc36d | AR137: 0|i001sf: | AS137: Semana 9 | AU137: 15.0 | AY137: Por hacer | AZ137: 45970.474 | BA137: 10239 | BB137: MIP-120 | BC137: Mostrar lista de amistades
A138: Condicionar la visibilidad del botón según el estado de amistad | B138: MIP-321 | C138: 10670 | D138: Subtarea | E138: Tareas por hacer | F138: MIP | G138: Proyecto Intermodular | H138: software | I138: Alberto Puig Parellada | J138: 712020:5af7a3fc-6e7a-4877-a93a-01a122fcc36d | L138: Medium | N138: Alberto Puig Parellada | O138: 712020:5af7a3fc-6e7a-4877-a93a-01a122fcc36d | P138: Alberto Puig Parellada | Q138: 712020:5af7a3fc-6e7a-4877-a93a-01a122fcc36d | R138: Alberto Puig Parellada | S138: 712020:5af7a3fc-6e7a-4877-a93a-01a122fcc36d | T138: 45970.474 | U138: 45982.856 | Y138: 0 | Z138: Asegurarse de que el botón solo se muestre a usuarios que aún no son amigos, ocultándolo en caso contrario. | AB138: Alberto Puig Parellada | AC138: 712020:5af7a3fc-6e7a-4877-a93a-01a122fcc36d | AR138: 0|i001s7: | AS138: Semana 9 | AU138: 11.0 | AY138: Por hacer | AZ138: 45970.474 | BA138: 10236 | BB138: MIP-118 | BC138: Mostrar botón de añadir amigo
A139: Implementar la lógica para mostrar el botón de añadir amigo | B139: MIP-320 | C139: 10673 | D139: Subtarea | E139: Tareas por hacer | F139: MIP | G139: Proyecto Intermodular | H139: software | I139: Alberto Puig Parellada | J139: 712020:5af7a3fc-6e7a-4877-a93a-01a122fcc36d | L139: Medium | N139: Alberto Puig Parellada | O139: 712020:5af7a3fc-6e7a-4877-a93a-01a122fcc36d | P139: Alberto Puig Parellada | Q139: 712020:5af7a3fc-6e7a-4877-a93a-01a122fcc36d | R139: Alberto Puig Parellada | S139: 712020:5af7a3fc-6e7a-4877-a93a-01a122fcc36d | T139: 45970.474 | U139: 45982.856 | Y139: 0 | Z139: Desarrollar el código necesario para que el botón de añadir amigo se muestre en la interfaz de usuario en los lugares apropiados. | AB139: Alberto Puig Parellada | AC139: 712020:5af7a3fc-6e7a-4877-a93a-01a122fcc36d | AR139: 0|i001rz: | AS139: Semana 9 | AU139: 11.0 | AY139: Por hacer | AZ139: 45970.474 | BA139: 10236 | BB139: MIP-118 | BC139: Mostrar botón de añadir amigo
A140: Realizar pruebas de visualización del botón de añadir amigo | B140: MIP-319 | C140: 10672 | D140: Subtarea | E140: Tareas por hacer | F140: MIP | G140: Proyecto Intermodular | H140: software | I140: Alberto Puig Parellada | J140: 712020:5af7a3fc-6e7a-4877-a93a-01a122fcc36d | L140: Medium | N140: Alberto Puig Parellada | O140: 712020:5af7a3fc-6e7a-4877-a93a-01a122fcc36d | P140: Alberto Puig Parellada | Q140: 712020:5af7a3fc-6e7a-4877-a93a-01a122fcc36d | R140: Alberto Puig Parellada | S140: 712020:5af7a3fc-6e7a-4877-a93a-01a122fcc36d | T140: 45970.474 | U140: 45982.856 | Y140: 0 | Z140: Verificar que el botón se muestre correctamente en todos los dispositivos y resoluciones soportadas por la aplicación. | AB140: Alberto Puig Parellada | AC140: 712020:5af7a3fc-6e7a-4877-a93a-01a122fcc36d | AR140: 0|i001rr: | AS140: Semana 9 | AU140: 11.0 | AY140: Por hacer | AZ140: 45970.474 | BA140: 10236 | BB140: MIP-118 | BC140: Mostrar botón de añadir amigo
A141: Diseñar el botón de añadir amigo | B141: MIP-318 | C141: 10669 | D141: Subtarea | E141: Tareas por hacer | F141: MIP | G141: Proyecto Intermodular | H141: software | I141: Alberto Puig Parellada | J141: 712020:5af7a3fc-6e7a-4877-a93a-01a122fcc36d | L141: Medium | N141: Alberto Puig Parellada | O141: 712020:5af7a3fc-6e7a-4877-a93a-01a122fcc36d | P141: Alberto Puig Parellada | Q141: 712020:5af7a3fc-6e7a-4877-a93a-01a122fcc36d | R141: Alberto Puig Parellada | S141: 712020:5af7a3fc-6e7a-4877-a93a-01a122fcc36d | T141: 45970.474 | U141: 45982.856 | Y141: 0 | Z141: Crear el diseño visual del botón de añadir amigo siguiendo la guía de estilos de la aplicación. | AB141: Alberto Puig Parellada | AC141: 712020:5af7a3fc-6e7a-4877-a93a-01a122fcc36d | AR141: 0|i001rj: | AS141: Semana 9 | AU141: 11.0 | AY141: Por hacer | AZ141: 45970.474 | BA141: 10236 | BB141: MIP-118 | BC141: Mostrar botón de añadir amigo
A142: Mostrar información básica del usuario en el perfil | B142: MIP-317 | C142: 10665 | D142: Subtarea | E142: Tareas por hacer | F142: MIP | G142: Proyecto Intermodular | H142: software | I142: Alberto Puig Parellada | J142: 712020:5af7a3fc-6e7a-4877-a93a-01a122fcc36d | L142: Medium | N142: Alberto Puig Parellada | O142: 712020:5af7a3fc-6e7a-4877-a93a-01a122fcc36d | P142: Alberto Puig Parellada | Q142: 712020:5af7a3fc-6e7a-4877-a93a-01a122fcc36d | R142: Alberto Puig Parellada | S142: 712020:5af7a3fc-6e7a-4877-a93a-01a122fcc36d | T142: 45970.474 | U142: 45982.856 | Y142: 0 | Z142: Desplegar datos como nombre, foto, biografía y otra información relevante en la pantalla de perfil. | AB142: Alberto Puig Parellada | AC142: 712020:5af7a3fc-6e7a-4877-a93a-01a122fcc36d | AR142: 0|i001rb: | AS142: Semana 9 | AU142: 10.0 | AY142: Por hacer | AZ142: 45970.474 | BA142: 10234 | BB142: MIP-117 | BC142: Ver detalles del perfil de un usuario
A143: Agregar opción para reportar usuario desde el perfil | B143: MIP-316 | C143: 10664 | D143: Subtarea | E143: Tareas por hacer | F143: MIP | G143: Proyecto Intermodular | H143: software | I143: Alberto Puig Parellada | J143: 712020:5af7a3fc-6e7a-4877-a93a-01a122fcc36d | L143: Medium | N143: Alberto Puig Parellada | O143: 712020:5af7a3fc-6e7a-4877-a93a-01a122fcc36d | P143: Alberto Puig Parellada | Q143: 712020:5af7a3fc-6e7a-4877-a93a-01a122fcc36d | R143: Alberto Puig Parellada | S143: 712020:5af7a3fc-6e7a-4877-a93a-01a122fcc36d | T143: 45970.474 | U143: 45982.856 | Y143: 0 | Z143: Implementar un botón o enlace que permita a los usuarios reportar a otro usuario directamente desde su perfil. | AB143: Alberto Puig Parellada | AC143: 712020:5af7a3fc-6e7a-4877-a93a-01a122fcc36d | AR143: 0|i001r3: | AS143: Semana 9 | AU143: 10.0 | AY143: Por hacer | AZ143: 45970.474 | BA143: 10234 | BB143: MIP-117 | BC143: Ver detalles del perfil de un usuario
A144: Agregar opción para añadir usuario como amigo desde el perfil | B144: MIP-315 | C144: 10662 | D144: Subtarea | E144: Tareas por hacer | F144: MIP | G144: Proyecto Intermodular | H144: software | I144: Alberto Puig Parellada | J144: 712020:5af7a3fc-6e7a-4877-a93a-01a122fcc36d | L144: Medium | N144: Alberto Puig Parellada | O144: 712020:5af7a3fc-6e7a-4877-a93a-01a122fcc36d | P144: Alberto Puig Parellada | Q144: 712020:5af7a3fc-6e7a-4877-a93a-01a122fcc36d | R144: Alberto Puig Parellada | S144: 712020:5af7a3fc-6e7a-4877-a93a-01a122fcc36d | T144: 45970.474 | U144: 45982.856 | Y144: 0 | Z144: Incluir una funcionalidad que permita enviar una solicitud de amistad al usuario desde su perfil. | AB144: Alberto Puig Parellada | AC144: 712020:5af7a3fc-6e7a-4877-a93a-01a122fcc36d | AR144: 0|i001qv: | AS144: Semana 9 | AU144: 10.0 | AY144: Por hacer | AZ144: 45970.474 | BA144: 10234 | BB144: MIP-117 | BC144: Ver detalles del perfil de un usuario
A145: Implementar la obtención de datos del perfil de usuario | B145: MIP-314 | C145: 10663 | D145: Subtarea | E145: Tareas por hacer | F145: MIP | G145: Proyecto Intermodular | H145: software | I145: Alberto Puig Parellada | J145: 712020:5af7a3fc-6e7a-4877-a93a-01a122fcc36d | L145: Medium | N145: Alberto Puig Parellada | O145: 712020:5af7a3fc-6e7a-4877-a93a-01a122fcc36d | P145: Alberto Puig Parellada | Q145: 712020:5af7a3fc-6e7a-4877-a93a-01a122fcc36d | R145: Alberto Puig Parellada | S145: 712020:5af7a3fc-6e7a-4877-a93a-01a122fcc36d | T145: 45970.474 | U145: 45982.856 | Y145: 0 | Z145: Desarrollar la lógica para recuperar la información del perfil de usuario desde la base de datos o API. | AB145: Alberto Puig Parellada | AC145: 712020:5af7a3fc-6e7a-4877-a93a-01a122fcc36d | AR145: 0|i001qf: | AS145: Semana 9 | AU145: 10.0 | AY145: Por hacer | AZ145: 45970.474 | BA145: 10234 | BB145: MIP-117 | BC145: Ver detalles del perfil de un usuario
A146: Realizar pruebas de visualización y funcionalidad del perfil de usuario | B146: MIP-313 | C146: 10660 | D146: Subtarea | E146: Tareas por hacer | F146: MIP | G146: Proyecto Intermodular | H146: software | I146: Alberto Puig Parellada | J146: 712020:5af7a3fc-6e7a-4877-a93a-01a122fcc36d | L146: Medium | N146: Alberto Puig Parellada | O146: 712020:5af7a3fc-6e7a-4877-a93a-01a122fcc36d | P146: Alberto Puig Parellada | Q146: 712020:5af7a3fc-6e7a-4877-a93a-01a122fcc36d | R146: Alberto Puig Parellada | S146: 712020:5af7a3fc-6e7a-4877-a93a-01a122fcc36d | T146: 45970.474 | U146: 45982.856 | Y146: 0 | Z146: Probar que la información se muestra correctamente y que las acciones (reportar, añadir amigo) funcionan como se espera. | AB146: Alberto Puig Parellada | AC146: 712020:5af7a3fc-6e7a-4877-a93a-01a122fcc36d | AR146: 0|i001qn: | AS146: Semana 9 | AU146: 10.0 | AY146: Por hacer | AZ146: 45970.474 | BA146: 10234 | BB146: MIP-117 | BC146: Ver detalles del perfil de un usuario
A147: Realizar pruebas de usabilidad del botón de ver perfil | B147: MIP-312 | C147: 10655 | D147: Subtarea | E147: Tareas por hacer | F147: MIP | G147: Proyecto Intermodular | H147: software | I147: Alberto Puig Parellada | J147: 712020:5af7a3fc-6e7a-4877-a93a-01a122fcc36d | L147: Medium | N147: Alberto Puig Parellada | O147: 712020:5af7a3fc-6e7a-4877-a93a-01a122fcc36d | P147: Alberto Puig Parellada | Q147: 712020:5af7a3fc-6e7a-4877-a93a-01a122fcc36d | R147: Alberto Puig Parellada | S147: 712020:5af7a3fc-6e7a-4877-a93a-01a122fcc36d | T147: 45970.474 | U147: 45982.856 | Y147: 0 | Z147: Probar la funcionalidad del botón de ver perfil en las secciones de quedadas, grupos y chats para asegurar que es accesible y funciona correctamente. | AB147: Alberto Puig Parellada | AC147: 712020:5af7a3fc-6e7a-4877-a93a-01a122fcc36d | AR147: 0|i001q7: | AS147: Semana 9 | AU147: 11.0 | AY147: Por hacer | AZ147: 45970.474 | BA147: 10232 | BB147: MIP-116 | BC147: Mostrar botón de ver usuario en los usuarios de las quedadas, grupos y chats
A148: Implementar el botón de ver perfil en la lista de usuarios de grupos | B148: MIP-309 | C148: 10653 | D148: Subtarea | E148: Tareas por hacer | F148: MIP | G148: Proyecto Intermodular | H148: software | I148: Alberto Puig Parellada | J148: 712020:5af7a3fc-6e7a-4877-a93a-01a122fcc36d | L148: Medium | N148: Alberto Puig Parellada | O148: 712020:5af7a3fc-6e7a-4877-a93a-01a122fcc36d | P148: Alberto Puig Parellada | Q148: 712020:5af7a3fc-6e7a-4877-a93a-01a122fcc36d | R148: Alberto Puig Parellada | S148: 712020:5af7a3fc-6e7a-4877-a93a-01a122fcc36d | T148: 45970.474 | U148: 45982.856 | Y148: 0 | Z148: Agregar el botón de ver perfil junto a cada usuario en la sección de grupos, permitiendo la navegación al perfil del usuario seleccionado. | AB148: Alberto Puig Parellada | AC148: 712020:5af7a3fc-6e7a-4877-a93a-01a122fcc36d | AR148: 0|i001pz: | AS148: Semana 9 | AU148: 11.0 | AY148: Por hacer | AZ148: 45970.474 | BA148: 10232 | BB148: MIP-116 | BC148: Mostrar botón de ver usuario en los usuarios de las quedadas, grupos y chats
... A335: Mostrar botón de modificar quedada | B335: MIP-124 | C335: 10247 | D335: Historia | E335: Tareas por hacer | F335: MIP | G335: Proyecto Intermodular | H335: software | I335: Alberto Puig Parellada | J335: 712020:5af7a3fc-6e7a-4877-a93a-01a122fcc36d | L335: Medium | N335: Alberto Puig Parellada | O335: 712020:5af7a3fc-6e7a-4877-a93a-01a122fcc36d | P335: Alberto Puig Parellada | Q335: 712020:5af7a3fc-6e7a-4877-a93a-01a122fcc36d | R335: Alberto Puig Parellada | S335: 712020:5af7a3fc-6e7a-4877-a93a-01a122fcc36d | T335: 45968.543 | U335: 45983.059 | Y335: 0 | Z335: Como usuario creador/administrador de una quedada quiero ver un botón de modificar quedada para ver el formulario de modificación de la quedada | AB335: Alberto Puig Parellada | AC335: 712020:5af7a3fc-6e7a-4877-a93a-01a122fcc36d | AR335: 0|hzzzzy:zzzzzzi | AS335: Semanas 11 - 12 | AU335: 50.0 | AY335: Por hacer | AZ335: 45968.543 | BA335: 10228 | BB335: MIP-113 | BC335: Modificación de una quedada con confirmación
A336: Confirmar filtros | B336: MIP-123 | C336: 10245 | D336: Historia | E336: Tareas por hacer | F336: MIP | G336: Proyecto Intermodular | H336: software | I336: Alberto Puig Parellada | J336: 712020:5af7a3fc-6e7a-4877-a93a-01a122fcc36d | L336: Medium | N336: Alberto Puig Parellada | O336: 712020:5af7a3fc-6e7a-4877-a93a-01a122fcc36d | P336: Alberto Puig Parellada | Q336: 712020:5af7a3fc-6e7a-4877-a93a-01a122fcc36d | R336: Alberto Puig Parellada | S336: 712020:5af7a3fc-6e7a-4877-a93a-01a122fcc36d | T336: 45968.54 | U336: 45983.078 | V336: 45982.809 | Y336: 0 | Z336: Como usuario quiero poder aplicar los filtros escogidos a la hora de buscar los usuarios añadidos a amigos para que éstos se apliquen y se muestren los resultados de mi búsqueda | AB336: Alberto Puig Parellada | AC336: 712020:5af7a3fc-6e7a-4877-a93a-01a122fcc36d | AR336: 0|hzzzzy:zzzzzi | AS336: Semana 9 | AU336: 17.0 | AY336: Por hacer | AZ336: 45968.54 | BA336: 10237 | BB336: MIP-119 | BC336: Lista de amistades
A337: Mostrar filtros de búsqueda | B337: MIP-122 | C337: 10243 | D337: Historia | E337: Tareas por hacer | F337: MIP | G337: Proyecto Intermodular | H337: software | I337: Alberto Puig Parellada | J337: 712020:5af7a3fc-6e7a-4877-a93a-01a122fcc36d | L337: Medium | N337: Alberto Puig Parellada | O337: 712020:5af7a3fc-6e7a-4877-a93a-01a122fcc36d | P337: Alberto Puig Parellada | Q337: 712020:5af7a3fc-6e7a-4877-a93a-01a122fcc36d | R337: Alberto Puig Parellada | S337: 712020:5af7a3fc-6e7a-4877-a93a-01a122fcc36d | T337: 45968.54 | U337: 45983.078 | Y337: 0 | Z337: Como usuario quiero ver los filtros que hay disponibles para poder buscar mis usuarios añadidos como amigos según el criterio escogido | AB337: Alberto Puig Parellada | AC337: 712020:5af7a3fc-6e7a-4877-a93a-01a122fcc36d | AR337: 0|hzzzzy:zzzzx | AS337: Semana 9 | AU337: 16.0 | AY337: Por hacer | AZ337: 45968.54 | BA337: 10237 | BB337: MIP-119 | BC337: Lista de amistades
A338: Mostrar barra de búsqueda | B338: MIP-121 | C338: 10241 | D338: Historia | E338: Tareas por hacer | F338: MIP | G338: Proyecto Intermodular | H338: software | I338: Alberto Puig Parellada | J338: 712020:5af7a3fc-6e7a-4877-a93a-01a122fcc36d | L338: Medium | N338: Alberto Puig Parellada | O338: 712020:5af7a3fc-6e7a-4877-a93a-01a122fcc36d | P338: Alberto Puig Parellada | Q338: 712020:5af7a3fc-6e7a-4877-a93a-01a122fcc36d | R338: Alberto Puig Parellada | S338: 712020:5af7a3fc-6e7a-4877-a93a-01a122fcc36d | T338: 45968.54 | U338: 45983.078 | Y338: 0 | Z338: Como usuario quiero ver una barra de búsqueda para poder buscar usuarios por texto | AB338: Alberto Puig Parellada | AC338: 712020:5af7a3fc-6e7a-4877-a93a-01a122fcc36d | AR338: 0|hzzzzy:zzzzr | AS338: Semana 9 | AU338: 16.0 | AY338: Por hacer | AZ338: 45968.54 | BA338: 10237 | BB338: MIP-119 | BC338: Lista de amistades
A339: Mostrar lista de amistades | B339: MIP-120 | C339: 10239 | D339: Historia | E339: Tareas por hacer | F339: MIP | G339: Proyecto Intermodular | H339: software | I339: Alberto Puig Parellada | J339: 712020:5af7a3fc-6e7a-4877-a93a-01a122fcc36d | L339: Medium | N339: Alberto Puig Parellada | O339: 712020:5af7a3fc-6e7a-4877-a93a-01a122fcc36d | P339: Alberto Puig Parellada | Q339: 712020:5af7a3fc-6e7a-4877-a93a-01a122fcc36d | R339: Alberto Puig Parellada | S339: 712020:5af7a3fc-6e7a-4877-a93a-01a122fcc36d | T339: 45968.54 | U339: 45983.078 | V339: 45982.824 | Y339: 0 | Z339: Como usuario quiero poder ver mi lista de amistades para saber y gestionar los usuarios que he añadido como amigos | AB339: Alberto Puig Parellada | AC339: 712020:5af7a3fc-6e7a-4877-a93a-01a122fcc36d | AR339: 0|hzzzzy:zzzz | AS339: Semana 9 | AU339: 15.0 | AY339: Por hacer | AZ339: 45968.54 | BA339: 10237 | BB339: MIP-119 | BC339: Lista de amistades
A340: Lista de amistades | B340: MIP-119 | C340: 10237 | D340: Epic | E340: Tareas por hacer | F340: MIP | G340: Proyecto Intermodular | H340: software | I340: Alberto Puig Parellada | J340: 712020:5af7a3fc-6e7a-4877-a93a-01a122fcc36d | L340: Medium | N340: Alberto Puig Parellada | O340: 712020:5af7a3fc-6e7a-4877-a93a-01a122fcc36d | P340: Alberto Puig Parellada | Q340: 712020:5af7a3fc-6e7a-4877-a93a-01a122fcc36d | R340: Alberto Puig Parellada | S340: 712020:5af7a3fc-6e7a-4877-a93a-01a122fcc36d | T340: 45968.539 | U340: 45983.078 | V340: 45983.435 | Y340: 0 | AB340: Alberto Puig Parellada | AC340: 712020:5af7a3fc-6e7a-4877-a93a-01a122fcc36d | AQ340: purple | AR340: 0|i00030:i | AU340: 15.0 | AY340: Por hacer | AZ340: 45968.539
A341: Mostrar botón de añadir amigo | B341: MIP-118 | C341: 10236 | D341: Historia | E341: Tareas por hacer | F341: MIP | G341: Proyecto Intermodular | H341: software | I341: Alberto Puig Parellada | J341: 712020:5af7a3fc-6e7a-4877-a93a-01a122fcc36d | L341: Medium | N341: Alberto Puig Parellada | O341: 712020:5af7a3fc-6e7a-4877-a93a-01a122fcc36d | P341: Alberto Puig Parellada | Q341: 712020:5af7a3fc-6e7a-4877-a93a-01a122fcc36d | R341: Alberto Puig Parellada | S341: 712020:5af7a3fc-6e7a-4877-a93a-01a122fcc36d | T341: 45968.538 | U341: 45983.535 | V341: 45983.535 | Y341: 0 | Z341: Como usuario quiero ver un botón de añadir amigo en los usuario sq ue vea en la web para poder añadir al usuario a mi lista de amigos | AB341: Alberto Puig Parellada | AC341: 712020:5af7a3fc-6e7a-4877-a93a-01a122fcc36d | AR341: 0|hzzzzy:zzzv | AS341: Semana 9 | AU341: 11.0 | AY341: Por hacer | AZ341: 45968.538 | BA341: 10227 | BB341: MIP-112 | BC341: Añadir usuarios amigos
A342: Ver detalles del perfil de un usuario | B342: MIP-117 | C342: 10234 | D342: Historia | E342: Tareas por hacer | F342: MIP | G342: Proyecto Intermodular | H342: software | I342: Alberto Puig Parellada | J342: 712020:5af7a3fc-6e7a-4877-a93a-01a122fcc36d | L342: Medium | N342: Alberto Puig Parellada | O342: 712020:5af7a3fc-6e7a-4877-a93a-01a122fcc36d | P342: Alberto Puig Parellada | Q342: 712020:5af7a3fc-6e7a-4877-a93a-01a122fcc36d | R342: Alberto Puig Parellada | S342: 712020:5af7a3fc-6e7a-4877-a93a-01a122fcc36d | T342: 45968.536 | U342: 45983.078 | Y342: 0 | Z342: Como usuario quiero ver la información del perfil del usuario para poder conocer más acerca de un usuario o realizar acciones como reportar o añadir a amigos | AB342: Alberto Puig Parellada | AC342: 712020:5af7a3fc-6e7a-4877-a93a-01a122fcc36d | AR342: 0|hzzzzy:zzzi | AS342: Semana 9 | AU342: 10.0 | AY342: Por hacer | AZ342: 45968.536 | BA342: 10230 | BB342: MIP-115 | BC342: Ver perfiles de otros usuarios
A343: Mostrar botón de ver usuario en los usuarios de las quedadas, grupos y chats | B343: MIP-116 | C343: 10232 | D343: Historia | E343: Tareas por hacer | F343: MIP | G343: Proyecto Intermodular | H343: software | I343: Alberto Puig Parellada | J343: 712020:5af7a3fc-6e7a-4877-a93a-01a122fcc36d | L343: Medium | N343: Alberto Puig Parellada | O343: 712020:5af7a3fc-6e7a-4877-a93a-01a122fcc36d | P343: Alberto Puig Parellada | Q343: 712020:5af7a3fc-6e7a-4877-a93a-01a122fcc36d | R343: Alberto Puig Parellada | S343: 712020:5af7a3fc-6e7a-4877-a93a-01a122fcc36d | T343: 45968.535 | U343: 45983.078 | Y343: 0 | Z343: Como usuario quiero ver un botón de ver perfil en los usuarios que se muestren en la aplicación para poder acceder a la información del perfil del usuario | AB343: Alberto Puig Parellada | AC343: 712020:5af7a3fc-6e7a-4877-a93a-01a122fcc36d | AR343: 0|hzzzzy:zzy | AS343: Semana 9 | AU343: 11.0 | AY343: Por hacer | AZ343: 45968.535 | BA343: 10230 | BB343: MIP-115 | BC343: Ver perfiles de otros usuarios
A344: Ver perfiles de otros usuarios | B344: MIP-115 | C344: 10230 | D344: Epic | E344: Tareas por hacer | F344: MIP | G344: Proyecto Intermodular | H344: software | I344: Alberto Puig Parellada | J344: 712020:5af7a3fc-6e7a-4877-a93a-01a122fcc36d | L344: Medium | N344: Alberto Puig Parellada | O344: 712020:5af7a3fc-6e7a-4877-a93a-01a122fcc36d | P344: Alberto Puig Parellada | Q344: 712020:5af7a3fc-6e7a-4877-a93a-01a122fcc36d | R344: Alberto Puig Parellada | S344: 712020:5af7a3fc-6e7a-4877-a93a-01a122fcc36d | T344: 45968.535 | U344: 45983.078 | Y344: 0 | AB344: Alberto Puig Parellada | AC344: 712020:5af7a3fc-6e7a-4877-a93a-01a122fcc36d | AQ344: purple | AR344: 0|i00030: | AU344: 10.0 | AY344: Por hacer | AZ344: 45968.535
A345: Eliminación de una quedada con confirmación | B345: MIP-114 | C345: 10229 | D345: Epic | E345: Tareas por hacer | F345: MIP | G345: Proyecto Intermodular | H345: software | I345: Alberto Puig Parellada | J345: 712020:5af7a3fc-6e7a-4877-a93a-01a122fcc36d | L345: Medium | N345: Alberto Puig Parellada | O345: 712020:5af7a3fc-6e7a-4877-a93a-01a122fcc36d | P345: Alberto Puig Parellada | Q345: 712020:5af7a3fc-6e7a-4877-a93a-01a122fcc36d | R345: Alberto Puig Parellada | S345: 712020:5af7a3fc-6e7a-4877-a93a-01a122fcc36d | T345: 45968.533 | U345: 45983.084 | Y345: 0 | AB345: Alberto Puig Parellada | AC345: 712020:5af7a3fc-6e7a-4877-a93a-01a122fcc36d | AL345: MIP-5 | AQ345: purple | AR345: 0|i00017: | AU345: 45.0 | AY345: Por hacer | AZ345: 45968.533
A346: Modificación de una quedada con confirmación | B346: MIP-113 | C346: 10228 | D346: Epic | E346: Tareas por hacer | F346: MIP | G346: Proyecto Intermodular | H346: software | I346: Alberto Puig Parellada | J346: 712020:5af7a3fc-6e7a-4877-a93a-01a122fcc36d | L346: Medium | N346: Alberto Puig Parellada | O346: 712020:5af7a3fc-6e7a-4877-a93a-01a122fcc36d | P346: Alberto Puig Parellada | Q346: 712020:5af7a3fc-6e7a-4877-a93a-01a122fcc36d | R346: Alberto Puig Parellada | S346: 712020:5af7a3fc-6e7a-4877-a93a-01a122fcc36d | T346: 45968.533 | U346: 45983.085 | Y346: 0 | AB346: Alberto Puig Parellada | AC346: 712020:5af7a3fc-6e7a-4877-a93a-01a122fcc36d | AL346: MIP-5 | AQ346: purple | AR346: 0|i00013: | AU346: 50.0 | AY346: Por hacer | AZ346: 45968.533
...

Sheet Limpio
A1: Resumen | B1: Tipo | C1: Estado | D1: Descripción | E1: Persona asignada | F1: Campo personalizado (Story point estimate) | G1: Campo personalizado (Start date) | H1: Fecha de vencimiento | I1: Sprint
A2: Integrar sistema de notificaciones con el flujo de compra | B2: Subtarea | C2: Tareas por hacer | D2: Asegurarse de que la notificación por correo electrónico se envíe automáticamente al finalizar el proceso de compra exitosamente. | E2: Alberto Puig Parellada | F2: 43.0 | G2: =VLOOKUP(I2,Sprints!$A$2:$C$100, 2, FALSE) -> 46125 | I2: Semanas 17 - 18
A3: Realizar pruebas de envío de notificaciones por correo electrónico | B3: Subtarea | C3: Tareas por hacer | D3: Probar el envío de correos electrónicos para verificar que la información enviada sea correcta y que el correo llegue al destinatario. | E3: Alberto Puig Parellada | F3: 43.0 | G3: =VLOOKUP(I3,Sprints!$A$2:$C$100, 2, FALSE) -> 46125 | I3: Semanas 17 - 18
A4: Implementar lógica para generar y enviar notificación por correo electrónico | B4: Subtarea | C4: Tareas por hacer | D4: Desarrollar la funcionalidad que genere y envíe el correo electrónico al usuario después de realizar una compra, utilizando la plantilla diseñada. | E4: Alberto Puig Parellada | F4: 43.0 | G4: =VLOOKUP(I4,Sprints!$A$2:$C$100, 2, FALSE) -> 46125 | I4: Semanas 17 - 18
A5: Documentar el proceso de notificación por correo electrónico | B5: Subtarea | C5: Tareas por hacer | D5: Crear documentación técnica y de usuario sobre cómo funciona el sistema de notificaciones por correo electrónico y qué información se incluye. | E5: Alberto Puig Parellada | F5: 43.0 | G5: =VLOOKUP(I5,Sprints!$A$2:$C$100, 2, FALSE) -> 46125 | I5: Semanas 17 - 18
A6: Mostrar mensajes de éxito o error tras el pago | B6: Subtarea | C6: Tareas por hacer | D6: Implementar la lógica para mostrar mensajes claros al usuario según el resultado del intento de pago (éxito, error, datos incorrectos, etc.). | E6: Alberto Puig Parellada | F6: 52.0 | G6: =VLOOKUP(I6,Sprints!$A$2:$C$100, 2, FALSE) -> 46111 | I6: Semanas 15 - 16
A7: Probar el formulario de pago en diferentes dispositivos y navegadores | B7: Subtarea | C7: Tareas por hacer | D7: Realizar pruebas funcionales y de usabilidad del formulario de pago en distintos dispositivos y navegadores para asegurar su correcto funcionamiento. | E7: Alberto Puig Parellada | F7: 52.0 | G7: =VLOOKUP(I7,Sprints!$A$2:$C$100, 2, FALSE) -> 46111 | I7: Semanas 15 - 16
A8: Integrar el formulario con la pasarela de pago | B8: Subtarea | C8: Tareas por hacer | D8: Conectar el formulario de pago con la pasarela de pago seleccionada para procesar los pagos de la suscripción premium. | E8: Alberto Puig Parellada | F8: 52.0 | G8: =VLOOKUP(I8,Sprints!$A$2:$C$100, 2, FALSE) -> 46111 | I8: Semanas 15 - 16
A9: Implementar campos y validaciones del formulario de pago | B9: Subtarea | C9: Tareas por hacer | D9: Desarrollar los campos necesarios (nombre, número de tarjeta, fecha de expiración, CVV, etc.) y agregar validaciones para asegurar la correcta introducción de los datos. | E9: Alberto Puig Parellada | F9: 52.0 | G9: =VLOOKUP(I9,Sprints!$A$2:$C$100, 2, FALSE) -> 46111 | I9: Semanas 15 - 16
A10: Realizar pruebas de visualización de anuncios en diferentes dispositivos | B10: Subtarea | C10: Tareas por hacer | D10: Probar la correcta visualización y funcionamiento de los anuncios en las listas de quedadas en distintos dispositivos y resoluciones. | E10: Alberto Puig Parellada | F10: 22.0 | G10: =VLOOKUP(I10,Sprints!$A$2:$C$100, 2, FALSE) -> 46125 | I10: Semanas 17 - 18
A11: Implementar la lógica para mostrar anuncios solo a usuarios no premium | B11: Subtarea | C11: Tareas por hacer | D11: Desarrollar la funcionalidad que verifica el tipo de usuario y muestra anuncios únicamente a los usuarios no premium en las listas de quedadas. | E11: Alberto Puig Parellada | F11: 22.0 | G11: =VLOOKUP(I11,Sprints!$A$2:$C$100, 2, FALSE) -> 46125 | I11: Semanas 17 - 18
A12: Recopilar métricas básicas de visualización de anuncios | B12: Subtarea | C12: Tareas por hacer | D12: Implementar la recopilación de datos sobre la visualización de anuncios (impresiones, clics) para futuras mejoras y análisis. | E12: Alberto Puig Parellada | F12: 22.0 | G12: =VLOOKUP(I12,Sprints!$A$2:$C$100, 2, FALSE) -> 46125 | I12: Semanas 17 - 18
A13: Integrar el sistema de anuncios con el backend de las listas de quedadas | B13: Subtarea | C13: Tareas por hacer | D13: Conectar el sistema de anuncios existente o nuevo con el backend que gestiona las listas de quedadas para que los anuncios se carguen dinámicamente. | E13: Alberto Puig Parellada | F13: 22.0 | G13: =VLOOKUP(I13,Sprints!$A$2:$C$100, 2, FALSE) -> 46125 | I13: Semanas 17 - 18
... A339: Mostrar lista de amistades | B339: Historia | C339: Tareas por hacer | D339: Como usuario quiero poder ver mi lista de amistades para saber y gestionar los usuarios que he añadido como amigos | E339: Alberto Puig Parellada | F339: 15.0 | G339: =VLOOKUP(I339,Sprints!$A$2:$C$100, 2, FALSE) -> 46069 | I339: Semana 9
A340: Lista de amistades | B340: Epic | C340: Tareas por hacer | E340: Alberto Puig Parellada | F340: 15.0 | G340: =VLOOKUP(I340,Sprints!$A$2:$C$100, 2, FALSE) -> #N/A
A341: Mostrar botón de añadir amigo | B341: Historia | C341: Tareas por hacer | D341: Como usuario quiero ver un botón de añadir amigo en los usuario sq ue vea en la web para poder añadir al usuario a mi lista de amigos | E341: Alberto Puig Parellada | F341: 11.0 | G341: =VLOOKUP(I341,Sprints!$A$2:$C$100, 2, FALSE) -> 46069 | I341: Semana 9
A342: Ver detalles del perfil de un usuario | B342: Historia | C342: Tareas por hacer | D342: Como usuario quiero ver la información del perfil del usuario para poder conocer más acerca de un usuario o realizar acciones como reportar o añadir a amigos | E342: Alberto Puig Parellada | F342: 10.0 | G342: =VLOOKUP(I342,Sprints!$A$2:$C$100, 2, FALSE) -> 46069 | I342: Semana 9
A343: Mostrar botón de ver usuario en los usuarios de las quedadas, grupos y chats | B343: Historia | C343: Tareas por hacer | D343: Como usuario quiero ver un botón de ver perfil en los usuarios que se muestren en la aplicación para poder acceder a la información del perfil del usuario | E343: Alberto Puig Parellada | F343: 11.0 | G343: =VLOOKUP(I343,Sprints!$A$2:$C$100, 2, FALSE) -> 46069 | I343: Semana 9
A344: Ver perfiles de otros usuarios | B344: Epic | C344: Tareas por hacer | E344: Alberto Puig Parellada | F344: 10.0 | G344: =VLOOKUP(I344,Sprints!$A$2:$C$100, 2, FALSE) -> #N/A
A345: Eliminación de una quedada con confirmación | B345: Epic | C345: Tareas por hacer | E345: Alberto Puig Parellada | F345: 45.0 | G345: =VLOOKUP(I345,Sprints!$A$2:$C$100, 2, FALSE) -> #N/A
A346: Modificación de una quedada con confirmación | B346: Epic | C346: Tareas por hacer | E346: Alberto Puig Parellada | F346: 50.0 | G346: =VLOOKUP(I346,Sprints!$A$2:$C$100, 2, FALSE) -> #N/A
A347: Añadir usuarios amigos | B347: Epic | C347: Tareas por hacer | E347: Alberto Puig Parellada | F347: 10.0 | G347: =VLOOKUP(I347,Sprints!$A$2:$C$100, 2, FALSE) -> #N/A
A348: Crear endpoint para la verificación del correo electrónico | B348: Subtarea | C348: Tareas por hacer | D348: Desarrollar un endpoint que reciba la solicitud de verificación y valide el token enviado al correo del usuario. | E348: Alberto Puig Parellada | F348: 12.0 | G348: =VLOOKUP(I348,Sprints!$A$2:$C$100, 2, FALSE) -> 46013 | I348: Semana 1
A349: Implementar el envío automático del correo de confirmación | B349: Subtarea | C349: Tareas por hacer | D349: Desarrollar la funcionalidad que envía automáticamente el correo de confirmación al usuario después de que se registre. | E349: Alberto Puig Parellada | F349: 12.0 | G349: =VLOOKUP(I349,Sprints!$A$2:$C$100, 2, FALSE) -> 46013 | I349: Semana 1
A350: Gestionar mensajes de éxito y error en la verificación | B350: Subtarea | C350: Tareas por hacer | D350: Implementar mensajes claros para el usuario en caso de éxito o error al verificar su correo electrónico. | E350: Alberto Puig Parellada | F350: 12.0 | G350: =VLOOKUP(I350,Sprints!$A$2:$C$100, 2, FALSE) -> 46013 | I350: Semana 1
A351: Generar y almacenar el token de verificación | B351: Subtarea | C351: Tareas por hacer | D351: Crear un sistema para generar un token único de verificación y almacenarlo asociado al usuario para validar la confirmación del correo. | E351: Alberto Puig Parellada | F351: 12.0 | G351: =VLOOKUP(I351,Sprints!$A$2:$C$100, 2, FALSE) -> 46013 | I351: Semana 1
A352: Implementar el formulario de registro en la aplicación | B352: Subtarea | C352: Tareas por hacer | D352: Desarrollar el formulario de registro en la aplicación, asegurando que los campos sean interactivos y permitan la introducción de datos por parte del usuario. | E352: Alberto Puig Parellada | F352: 10.0 | G352: =VLOOKUP(I352,Sprints!$A$2:$C$100, 2, FALSE) -> 46013 | I352: Semana 1
A353: Validar los campos del formulario de registro | B353: Subtarea | C353: Tareas por hacer | D353: Agregar validaciones a los campos del formulario para asegurar que los datos introducidos por el usuario sean correctos (por ejemplo, formato de correo electrónico, longitud de la contraseña, campos obligatorios, etc.). | E353: Alberto Puig Parellada | F353: 10.0 | G353: =VLOOKUP(I353,Sprints!$A$2:$C$100, 2, FALSE) -> 46013 | I353: Semana 1
A354: Mostrar mensajes de error y éxito en el formulario de registro | B354: Subtarea | C354: Tareas por hacer | D354: Implementar la visualización de mensajes de error cuando los datos introducidos no sean válidos y mensajes de éxito cuando el registro se complete correctamente. | E354: Alberto Puig Parellada | F354: 10.0 | G354: =VLOOKUP(I354,Sprints!$A$2:$C$100, 2, FALSE) -> 46013 | I354: Semana 1
A355: Diseñar la interfaz del formulario de registro | B355: Subtarea | C355: Tareas por hacer | D355: Crear el diseño visual del formulario de registro, definiendo los campos necesarios (nombre, correo electrónico, contraseña, etc.) y la disposición de los elementos en la pantalla. | E355: Alberto Puig Parellada | F355: 10.0 | G355: =VLOOKUP(I355,Sprints!$A$2:$C$100, 2, FALSE) -> 46013 | I355: Semana 1
A356: Mostrar botón de imagen para enviar fotos | B356: Historia | C356: Tareas por hacer | D356: Como usuario perteneciente a un grupo/chat quiero ver un botón de imagen para poder enviar imágenes por el grupo/chat | E356: Alberto Puig Parellada | F356: 38.0 | G356: =VLOOKUP(I356,Sprints!$A$2:$C$100, 2, FALSE) -> 46097 | I356: Semanas 13 - 14
A357: Mostrar sección de texto para enviar un mensaje | B357: Historia | C357: Tareas por hacer | D357: Como usuario perteneciente a un grupo/chat quiero ver el cuadro de introducción de texto para poder enviar mensajes por el grupo/chat | E357: Alberto Puig Parellada | F357: 37.0 | G357: =VLOOKUP(I357,Sprints!$A$2:$C$100, 2, FALSE) -> 46097 | I357: Semanas 13 - 14
A358: Mostrar formulario de edición de los detalles del grupo | B358: Historia | C358: Tareas por hacer | D358: Como usuario administrador/creador de un grupo quiero ver el formulario de edición de los detalles del grupo para poder cambiar la información del grupo | E358: Alberto Puig Parellada | F358: 33.0 | G358: =VLOOKUP(I358,Sprints!$A$2:$C$100, 2, FALSE) -> 46083 | I358: Semanas 11 - 12
A359: Mostrar detalles del grupo | B359: Historia | C359: Tareas por hacer | D359: Como usuario de un grupo quiero poder ver los detalles del grupo como el nombre la descripción y la foto para saber en qué grupo estoy y para que se hizo el grupo | E359: Alberto Puig Parellada | F359: 31.0 | G359: =VLOOKUP(I359,Sprints!$A$2:$C$100, 2, FALSE) -> 46083 | I359: Semanas 11 - 12
... A373: Mostrar la lista de grupos y chats en los que el usuario participa | B373: Historia | C373: Tareas por hacer | D373: Como usuario quiero ver la lista de los grupos y los chats a los que pertenezco para poder entrar a ellos y chatear | E373: Alberto Puig Parellada | F373: 15.0 | G373: =VLOOKUP(I373,Sprints!$A$2:$C$100, 2, FALSE) -> 46083 | I373: Semanas 11 - 12
A374: Lista de grupos y chats del usuario con filtros | B374: Epic | C374: Tareas por hacer | E374: Alberto Puig Parellada | F374: 15.0 | G374: =VLOOKUP(I374,Sprints!$A$2:$C$100, 2, FALSE) -> #N/A
A375: Enviar notificación por correo electrónico | B375: Historia | C375: Tareas por hacer | D375: Como usuario quiero que me llegue al correo electrónico una notificación con el resumen de la compra realizada, los beneficios, la duración, el costo y otra información interesante para estar bien informado de y documentado del pago realizado | E375: Alberto Puig Parellada | F375: 43.0 | G375: =VLOOKUP(I375,Sprints!$A$2:$C$100, 2, FALSE) -> 46125 | I375: Semanas 17 - 18
A376: Confirmar suscripción premium | B376: Historia | C376: Tareas por hacer | D376: Como usuario quiero poder confirmar que estoy de acuerdo con todos los requisitos, beneficios y costos del premium para poder finalizar el proceso de cambio a cuenta premium | E376: Alberto Puig Parellada | F376: 54.0 | G376: =VLOOKUP(I376,Sprints!$A$2:$C$100, 2, FALSE) -> 46111 | I376: Semanas 15 - 16
A377: Mostrar formulario de pago para la suscripción premium | B377: Historia | C377: Tareas por hacer | D377: Como usuario quiero ver el formulario de pago de la suscripción premium para poder hacer el pago y tener mi cuenta premium | E377: Alberto Puig Parellada | F377: 52.0 | G377: =VLOOKUP(I377,Sprints!$A$2:$C$100, 2, FALSE) -> 46111 | I377: Semanas 15 - 16
A378: Mostrar ventajas y requisitos para el premium | B378: Historia | C378: Tareas por hacer | D378: Como usuario quiero ver todos los beneficios que me ofrece el hacerme premium y todos los requisitos que el premium requiere, como el costo, para saber si me interesa hacerme usuario premium | E378: Alberto Puig Parellada | F378: 50.0 | G378: =VLOOKUP(I378,Sprints!$A$2:$C$100, 2, FALSE) -> 46076 | I378: Semana 10
...

Sheet Ordenado
A1: Resumen | B1: Tipo | C1: Estado | D1: Descripción | E1: Persona asignada | F1: Story point | G1: Start Inicio | H1: Fecha Fin | I1: Sprint
A2: Ver perfiles de otros usuarios | B2: Epic | C2: Tareas por hacer | E2: Alberto Puig Parellada | F2: 10.0
A3: Añadir usuarios amigos | B3: Epic | C3: Tareas por hacer | E3: Alberto Puig Parellada | F3: 10.0
A4: Mostrar la información del usuario (Perfil) | B4: Epic | C4: Tareas por hacer | E4: Alberto Puig Parellada | F4: 10.0
A5: Sistema de reportes para las quedadas | B5: Epic | C5: Tareas por hacer | E5: Alberto Puig Parellada | F5: 10.0
A6: Creación de quedadas | B6: Epic | C6: Tareas por hacer | E6: Alberto Puig Parellada | F6: 10.0
A7: Registro para el usuario | B7: Epic | C7: Tareas por hacer | E7: Alberto Puig Parellada | F7: 10.0
A8: Lista de amistades | B8: Epic | C8: Tareas por hacer | E8: Alberto Puig Parellada | F8: 15.0
A9: Lista de grupos y chats del usuario con filtros | B9: Epic | C9: Tareas por hacer | E9: Alberto Puig Parellada | F9: 15.0
A10: Cambiar la infomación del usuario | B10: Epic | C10: Tareas por hacer | E10: Alberto Puig Parellada | F10: 15.0
A11: Inicio de sesión para el usuario | B11: Epic | C11: Tareas por hacer | E11: Alberto Puig Parellada | F11: 15.0
A12: Sistema de reportes de usuarios | B12: Epic | C12: Tareas por hacer | E12: Alberto Puig Parellada | F12: 15.0
A13: Búsqueda de quedadas con filtros | B13: Epic | C13: Tareas por hacer | E13: Alberto Puig Parellada | F13: 15.0
... A29: Confirmación puntuaciones asignadas a las quedadas | B29: Epic | C29: Tareas por hacer | E29: Alberto Puig Parellada | F29: 50.0
A30: Mostrar la información del usuario | B30: Historia | C30: Tareas por hacer | D30: Como usuario quiero ver mi información del perfil para comprobar que está bien y poder acceder a ella | E30: Alberto Puig Parellada | F30: 10.0 | G30: =VLOOKUP(I30,Sprints!$A$2:$C$100, 2, FALSE) -> 46013 | H30: =VLOOKUP(I30,Sprints!$A$2:$C$100, 2, FALSE) -> 46013 | I30: Semana 1
A31: Ver el formulario de creación de quedada | B31: Historia | C31: Tareas por hacer | D31: Como usuario quiero ver el formulario de crear quedadas para poder introducir los datos de mi quedada | E31: Alberto Puig Parellada | F31: 10.0 | G31: =VLOOKUP(I31,Sprints!$A$2:$C$100, 2, FALSE) -> 46013 | H31: =VLOOKUP(I31,Sprints!$A$2:$C$100, 2, FALSE) -> 46013 | I31: Semana 1
A32: Registrar al usuario | B32: Historia | C32: Tareas por hacer | D32: Como usuario quiero que se registre mi cuenta para poder usarla | E32: Alberto Puig Parellada | F32: 10.0 | G32: =VLOOKUP(I32,Sprints!$A$2:$C$100, 2, FALSE) -> 46013 | H32: =VLOOKUP(I32,Sprints!$A$2:$C$100, 2, FALSE) -> 46013 | I32: Semana 1
A33: Ver el formulario de registro | B33: Historia | C33: Tareas por hacer | D33: Como usuario quiero ver el formulario de registro para poder introducir mis datos y registrarme | E33: Alberto Puig Parellada | F33: 10.0 | G33: =VLOOKUP(I33,Sprints!$A$2:$C$100, 2, FALSE) -> 46013 | H33: =VLOOKUP(I33,Sprints!$A$2:$C$100, 2, FALSE) -> 46013 | I33: Semana 1
A34: Mostrar resumen de la quedada creada | B34: Historia | C34: Tareas por hacer | D34: Como usuario quiero ver un resumen de mi quedada creada para verificar que se ha creado bien y con los datos correctos | E34: Alberto Puig Parellada | F34: 11.0 | G34: =VLOOKUP(I34,Sprints!$A$2:$C$100, 2, FALSE) -> 46013 | H34: =VLOOKUP(I34,Sprints!$A$2:$C$100, 2, FALSE) -> 46013 | I34: Semana 1
A35: Crear la quedada | B35: Historia | C35: Tareas por hacer | D35: Como usuario quiero que la página cree mi quedada para poder usarla | E35: Alberto Puig Parellada | F35: 12.0 | G35: =VLOOKUP(I35,Sprints!$A$2:$C$100, 2, FALSE) -> 46013 | H35: =VLOOKUP(I35,Sprints!$A$2:$C$100, 2, FALSE) -> 46013 | I35: Semana 1
A36: Recibir notificación por correo | B36: Historia | C36: Tareas por hacer | D36: Como usuario quiero que se me envíe un correo de notificación al registrar mi cuenta | E36: Alberto Puig Parellada | F36: 12.0 | G36: =VLOOKUP(I36,Sprints!$A$2:$C$100, 2, FALSE) -> 46013 | H36: =VLOOKUP(I36,Sprints!$A$2:$C$100, 2, FALSE) -> 46013 | I36: Semana 1
A37: Enviar correo de confirmación | B37: Historia | C37: Tareas por hacer | D37: Como usuario quiero recibir un correo para que se verifique que he introducido bien mi correo electrónico | E37: Alberto Puig Parellada | F37: 12.0 | G37: =VLOOKUP(I37,Sprints!$A$2:$C$100, 2, FALSE) -> 46013 | H37: =VLOOKUP(I37,Sprints!$A$2:$C$100, 2, FALSE) -> 46013 | I37: Semana 1
A38: Ver el formulario de inicio de sesión | B38: Historia | C38: Tareas por hacer | D38: Como usuario quiero ver el formulario de inicio de sesión para poder introducir mi cuenta e iniciar sesión | E38: Alberto Puig Parellada | F38: 15.0 | G38: =VLOOKUP(I38,Sprints!$A$2:$C$100, 2, FALSE) -> 46013 | H38: =VLOOKUP(I38,Sprints!$A$2:$C$100, 2, FALSE) -> 46013 | I38: Semana 1
A39: Cambiar la contraseña | B39: Historia | C39: Tareas por hacer | D39: Como usuario quiero poder cambiar mi contraseña para poder seleccionar la que desee | E39: Alberto Puig Parellada | F39: 16.0 | G39: =VLOOKUP(I39,Sprints!$A$2:$C$100, 2, FALSE) -> 46013 | H39: =VLOOKUP(I39,Sprints!$A$2:$C$100, 2, FALSE) -> 46013 | I39: Semana 1
A40: Cambiar el correo | B40: Historia | C40: Tareas por hacer | D40: Como usuario quiero poder cambiar mi dirección de correo para poder seleccionar el que desee | E40: Alberto Puig Parellada | F40: 16.0 | G40: =VLOOKUP(I40,Sprints!$A$2:$C$100, 2, FALSE) -> 46013 | H40: =VLOOKUP(I40,Sprints!$A$2:$C$100, 2, FALSE) -> 46013 | I40: Semana 1
A41: Cambiar el nombre de usuario | B41: Historia | C41: Tareas por hacer | D41: Como usuario quiero poder cambiar mi nombre de usuario para poder seleccionar el que desee | E41: Alberto Puig Parellada | F41: 16.0 | G41: =VLOOKUP(I41,Sprints!$A$2:$C$100, 2, FALSE) -> 46013 | H41: =VLOOKUP(I41,Sprints!$A$2:$C$100, 2, FALSE) -> 46013 | I41: Semana 1
... A452: Actualizar el modelo de usuario para incluir el estado premium | B452: Subtarea | C452: Tareas por hacer | D452: Modificar el modelo de datos del usuario para asegurar que el estado premium/no premium esté disponible para ser mostrado en el perfil. | E452: Alberto Puig Parellada | F452: 50.0 | G452: =VLOOKUP(I452,Sprints!$A$2:$C$100, 2, FALSE) -> 46125 | H452: =VLOOKUP(I452,Sprints!$A$2:$C$100, 2, FALSE) -> 46125 | I452: Semanas 17 - 18

Sheet Sprints
A1: Sprint | B1: Fecha inicio | C1: Fecha fin
A2: Semana 1 | B2: 46013 | C2: 46020
A3: Semana 2 | B3: 46020 | C3: 46027
A4: Semana 3 | B4: 46027 | C4: 46034
A5: Semana 4 | B5: 46034 | C5: 46041
A6: Semana 5 | B6: 46041 | C6: 46048
A7: Semana 6 | B7: 46048 | C7: 46055
A8: Semana 7 | B8: 46055 | C8: 46062
A9: Semana 8 | B9: 46062 | C9: 46069
A10: Semana 9 | B10: 46069 | C10: 46076
A11: Semana 10 | B11: 46076 | C11: 46083
A12: Semanas 11 - 12 | B12: 46083 | C12: 46097
A13: Semanas 13 - 14 | B13: 46097 | C13: 46111
... A15: Semanas 17 - 18 | B15: 46125 | C15: 46139

Sheet Caracteres
A1: á | B1: á
A2: é | B2: é
A3: í | B3: í
A4: ó | B4: ó
A5: ú | B5: ú
A6: ñ | B6: ñ

Sheet Tabla1
A1: ID | B1: Historia de Usaurio | C1: Criterios de aceptación
A2: Ver perfiles de otros usuarios | B2: Epic | C2: Tareas por hacer | E2: Alberto Puig Parellada | F2: 10.0
A3: Añadir usuarios amigos | B3: Epic | C3: Tareas por hacer | E3: Alberto Puig Parellada | F3: 10.0
A4: Mostrar la información del usuario (Perfil) | B4: Epic | C4: Tareas por hacer | E4: Alberto Puig Parellada | F4: 10.0
A5: Sistema de reportes para las quedadas | B5: Epic | C5: Tareas por hacer | E5: Alberto Puig Parellada | F5: 10.0
A6: Creación de quedadas | B6: Epic | C6: Tareas por hacer | E6: Alberto Puig Parellada | F6: 10.0
A7: Registro para el usuario | B7: Epic | C7: Tareas por hacer | E7: Alberto Puig Parellada | F7: 10.0
